Workbook

Sheet 动作库
A1: 序号 | B1: 动作Key/ID | C1: 动作名称 | D1: 身体部位分类 | E1: 主要肌群 | F1: 次要肌群 | G1: 器械分类 | H1: 器械 | I1: 训练类型 | J1: 媒体类型 | K1: 本地媒体文件 | L1: 图片相对路径 | M1: 原始mp4字段 | N1: 主视频URL | O1: 动作讲解视频相对路径 | P1: 英文名 | Q1: 别名 | R1: 相关动作
A2: 1 | B2: 10431201 | C2: 负重颈弯举 | D2: 颈部 | G2: 其他 | H2: 杠铃、哑铃、颈部训练器、负重带 | I2: weight | J2: gif | K2: 0001_负重颈弯举_10431201.gif | L2: 训记_动作图片_GIF_按身体部位分类/images/颈部/0001_负重颈弯举_10431201.gif | M2: 10431201_withnewxunji.mp4 | P2: Weighted Neck Curl / Weighted Neck Flexion | Q2: 颈弯举、负重颈部弯举、颈部负重弯举 | R2: 徒手颈弯举、颈部抗阻屈伸、仰卧颈弯举
A3: 2 | B3: 13001201 | C3: 下斜悍马机推胸 | D3: 胸 | E3: 胸大肌、三角肌前束 | F3: 上胸、肱三头肌 | G3: 悍马机 | H3: 悍马器械、悍马机（Hammer Strength器械）、固定轨迹推胸器械 | I3: weight | J3: gif | K3: 0002_下斜悍马机推胸_13001201.gif | L3: 训记_动作图片_GIF_按身体部位分类/images/胸/0002_下斜悍马机推胸_13001201.gif | M3: 13001201-Lever-Decline-Chest-Press_Chest__withnewxunji.mp4 | P3: Decline Hammer Chest Press / Hammer Strength Decline Chest Press | Q3: 悍马机下斜推胸、下斜推胸（器械）、器械下斜推胸、哈克机下斜推胸 | R3: 平板悍马机推胸、上斜悍马机推胸、器械坐姿推胸
A4: 3 | B4: 13461201 | C4: 跪姿前伸手 | D4: 热身动作 | E4: 背阔肌、背 | F4: 三角肌后束 | G4: 自重 | H4: 自重、瑜伽垫 | I4: plus_weight | J4: gif | K4: 0003_跪姿前伸手_13461201.gif | L4: 训记_动作图片_GIF_按身体部位分类/images/热身动作/0003_跪姿前伸手_13461201.gif | M4: 13461201-Kneeling-Lat-Stretch_Back_withnewxunji.mp4 | P4: Kneeling Forward Reach / Kneeling Lat Stretch / Single-Arm Kneeling Reach | Q4: 跪姿前伸展、跪姿手臂前伸、跪姿背阔肌拉伸、单臂跪姿前伸 | R4: 猫牛式、站姿背阔肌拉伸、婴儿式
A5: 4 | B5: 13471201 | C5: 单手悍马机下拉 | D5: 背 | E5: 背阔肌、三角肌后束 | F5: 前臂、斜方肌 | G5: 悍马机 | H5: 悍马器械、悍马机（Hammer Strength器械） | I5: weight | J5: gif | K5: 0004_单手悍马机下拉_13471201.gif | L5: 训记_动作图片_GIF_按身体部位分类/images/背/0004_单手悍马机下拉_13471201.gif | M5: 13471201-Lever-One-Arm-Lateral-Wide-Pulldown-(plate-loaded)_Back_withnewxunji.mp4 | P5: Single-Arm Hammer Strength Lat Pulldown / One-Arm Hammer Lat Pulldown | Q5: 悍马机单手下拉、单臂悍马下拉、单手哈玛机下拉 | R5: 坐姿绳索高位下拉、单臂哑铃划船、直臂下压
A6: 5 | B6: 13501201 | C6: 器械划船1 | D6: 背 | E6: 背阔肌、三角肌后束 | F6: 前臂 | G6: 器械 | H6: 固定器械、划船器械、坐姿划船机 | I6: weight | J6: gif | K6: 0005_器械划船1_13501201.gif | L6: 训记_动作图片_GIF_按身体部位分类/images/背/0005_器械划船1_13501201.gif | M6: 13501201-Lever-Seated-Row_Back_withnewxunji.mp4 | P6: Machine Row / Seated Machine Row | Q6: 器械划船、坐姿器械划船、背部器械划船 | R6: 哑铃划船、杠铃划船、高位下拉
A7: 6 | B7: 15331201 | C7: 抓举 | D7: 腿 | E7: 股四头肌、腘绳肌 | F7: 臀大肌 | G7: 杠铃 | H7: 杠铃 | I7: weight | J7: gif | K7: 0006_抓举_15331201.gif | L7: 训记_动作图片_GIF_按身体部位分类/images/腿/0006_抓举_15331201.gif | M7: 15331201-Barbell-Snatch_Weightlifts__withnewxunji.mp4 | P7: Snatch / Barbell Snatch | Q7: 杠铃抓举、抓举动作、抓举训练 | R7: 高翻、硬拉、深蹲
A8: 7 | B8: 15971201 | C8: 史密斯罗马尼亚硬拉 | D8: 臀部 | E8: 臀中肌、腘绳肌 | F8: 臀大肌 | G8: 史密斯机 | H8: 史密斯机、杠铃（固定于史密斯机） | I8: weight | J8: gif | K8: 0007_史密斯罗马尼亚硬拉_15971201.gif | L8: 训记_动作图片_GIF_按身体部位分类/images/臀部/0007_史密斯罗马尼亚硬拉_15971201.gif | M8: 15971201-Smith-Stiff-Legged-Deadlift_Hips__withnewxunji.mp4 | P8: Smith Machine Romanian Deadlift / Smith RDL | Q8: 史密斯机罗马尼亚硬拉、罗马尼亚硬拉（史密斯机）、史密斯直腿硬拉 | R8: 传统罗马尼亚硬拉、哑铃罗马尼亚硬拉、史密斯臀桥
A9: 8 | B9: 18571201 | C9: 坐姿器械卷腹 | D9: 腹部 | E9: 腹直肌、腹斜肌 | G9: 器械 | H9: 固定器械、卷腹器械、腹部训练机 | I9: weight | J9: gif | K9: 0008_坐姿器械卷腹_18571201.gif | L9: 训记_动作图片_GIF_按身体部位分类/images/腹部/0008_坐姿器械卷腹_18571201.gif | M9: 18571201-Lever-Total-Abdominal-Crunch_Waist_withnewxunji.mp4 | P9: Seated Machine Crunch / Machine Crunch | Q9: 器械卷腹、坐姿卷腹、卷腹器械训练 | R9: 仰卧卷腹、绳索卷腹、悬垂举腿
A10: 9 | B10: 18651201 | C10: 对握引体向上 | D10: 背 | E10: 背阔肌、背 | F10: 三角肌后束、前臂、斜方肌、肱二头肌、肱二头肌外侧头 | G10: 自重 | H10: 自重、单杠、引体向上杆、健身房单杠 | I10: plus_weight | J10: gif | K10: 0009_对握引体向上_18651201.gif | L10: 训记_动作图片_GIF_按身体部位分类/images/背/0009_对握引体向上_18651201.gif | M10: 18651201-Hammer-Grip-Pull-up-on-Dip-Cage_Back_withnewxunji.mp4 | P10: Neutral-Grip Pull-Up / Hammer Grip Pull-Up / Parallel Grip Pull-Up | Q10: 反握引体向上、中性握引体向上、掌心相对引体向上 | R10: 正握引体向上、反握引体向上、宽握引体向上
A11: 10 | B11: 18761201 | C11: 悍马机侧平举 | D11: 肩 | E11: 三角肌中束、三角肌前束 | F11: 三角肌后束 | G11: 悍马机 | H11: 悍马器械、悍马机、固定器械 | I11: weight | J11: gif | K11: 0010_悍马机侧平举_18761201.gif | L11: 训记_动作图片_GIF_按身体部位分类/images/肩/0010_悍马机侧平举_18761201.gif | M11: 18761201-Lever-Lateral-Raise-hammer_withnewxunji.mp4 | P11: Hammer Machine Lateral Raise / Machine Lateral Raise | Q11: 侧平举（悍马机）、悍马侧平举、器械侧平举 | R11: 哑铃侧平举、绳索侧平举、坐姿器械推举
A12: 11 | B12: 21421201 | C12: 滑雪机 | D12: 有氧 | G12: 其他 | H12: 滑雪机 | I12: times | J12: gif | K12: 0011_滑雪机_21421201.gif | L12: 训记_动作图片_GIF_按身体部位分类/images/有氧/0011_滑雪机_21421201.gif | M12: 21421201-Ski-Ergometer_Cardio__withnewxunji.mp4 | P12: SkiErg / Ski Ergometer / Ski Machine | Q12: 滑雪机训练、滑雪机有氧、滑雪机运动、室内滑雪机 | R12: 划船机、椭圆机、登山机
A13: 12 | B13: 21461201 | C13: 器械臀冲 | D13: 臀部 | E13: 臀中肌、臀大肌 | F13: 腘绳肌 | G13: 器械 | H13: 固定器械、臀冲训练机、髋部推举器械、带臀垫和脚垫的固定器械 | I13: weight | J13: gif | K13: 0012_器械臀冲_21461201.gif | L13: 训记_动作图片_GIF_按身体部位分类/images/臀部/0012_器械臀冲_21461201.gif | M13: 21461201-Lever-Hip-Thrust_Hips_withnewxunji.mp4 | P13: Machine Hip Thrust / Hip Thrust Machine | Q13: 臀冲（器械版）、机器臀冲、坐姿器械臀冲、器械髋部推举 | R13: 杠铃臀冲、自重臀桥、史密斯机臀冲
A14: 13 | B14: 21501201 | C14: 弹力带侧躺腿外展 | D14: 臀部 | E14: 臀中肌、臀大肌 | G14: TRX&弹力带 | H14: 弹力带、阻力带 | I14: weight | J14: gif | K14: 0013_弹力带侧躺腿外展_21501201.gif | L14: 训记_动作图片_GIF_按身体部位分类/images/臀部/0013_弹力带侧躺腿外展_21501201.gif | M14: 21501201-Resistance-Band-Clam_Hips__withnewxunji.mp4 | P14: Banded Side-Lying Leg Abduction / Resistance Band Side Leg Lift | Q14: 侧躺弹力带腿外展、弹力带侧卧腿外展、侧卧弹力带臀中肌训练 | R14: 侧卧腿上抬、弹力带站姿腿外展、侧卧蚌式开合
A15: 14 | B15: 22211201 | C15: 哑铃上凳 | D15: 臀部 | E15: 股四头肌、臀大肌 | F15: 腘绳肌、臀中肌 | G15: 哑铃 | H15: 哑铃、训练凳（或台阶） | I15: weight | J15: gif | K15: 0014_哑铃上凳_22211201.gif | L15: 训记_动作图片_GIF_按身体部位分类/images/臀部/0014_哑铃上凳_22211201.gif | M15: 22211201-Dumbbell-Step-Up-(female)_Thighs__withnewxunji.mp4 | P15: Dumbbell Step-Up / DB Step Up | Q15: 上凳哑铃、哑铃踏凳、哑铃登阶 | R15: 杠铃上凳、徒手上凳、哑铃弓步
A16: 15 | B16: 22651201 | C16: 器械划船2 | D16: 背 | E16: 背阔肌、三角肌后束 | F16: 前臂 | G16: 器械 | H16: 固定器械、划船机、坐姿划船器械 | I16: weight | J16: gif | K16: 0015_器械划船2_22651201.gif | L16: 训记_动作图片_GIF_按身体部位分类/images/背/0015_器械划船2_22651201.gif | M16: 22651201-Lever-Seated-Row-(version-2)_Back_withnewxunji.mp4 | P16: Machine Row / Seated Machine Row | Q16: 器械划船、坐姿器械划船、机器划船 | R16: 杠铃划船、哑铃划船、高位下拉
A17: 16 | B17: 22861201 | C17: 器械驴踢 | D17: 臀部 | E17: 臀中肌、腘绳肌 | F17: 臀大肌 | G17: 器械 | H17: 固定器械、器械驴踢机、臀部训练机、固定式驴踢训练器 | I17: weight | J17: gif | K17: 0016_器械驴踢_22861201.gif | L17: 训记_动作图片_GIF_按身体部位分类/images/臀部/0016_器械驴踢_22861201.gif | M17: 22861201-Lever-Hip-Extension-(VERSION-2)_Hips__withnewxunji.mp4 | P17: Machine Donkey Kick / Cable Donkey Kick (machine version) | Q17: 驴踢（器械）、器械臀踢、机器驴踢、坐姿器械驴踢 | R17: 徒手驴踢、弹力带驴踢、跪姿后踢腿
A18: 17 | B18: 23131201 | C18: 绳索内收 | D18: 臀部 | E18: 臀中肌、臀大肌 | G18: 绳索 | H18: 绳索器械、龙门架、缆绳机 | I18: weight | J18: gif | K18: 0017_绳索内收_23131201.gif | L18: 训记_动作图片_GIF_按身体部位分类/images/臀部/0017_绳索内收_23131201.gif | M18: 23131201-Cable-Hip-Adduction-(female)_Hips_withnewxunji.mp4 | P18: Cable Hip Adduction / Cable Inner Thigh | Q18: 绳索臀内收、缆绳内收、绳索侧抬腿、绳索髋内收 | R18: 站姿绳索外展、侧卧髋内收、器械髋内收
A19: 18 | B19: 24081201 | C19: 上斜负重头后仰 | D19: 颈部 | G19: 其他 | H19: 上斜训练凳、杠铃片、颈后负重带 | I19: weight | J19: gif | K19: 0018_上斜负重头后仰_24081201.gif | L19: 训记_动作图片_GIF_按身体部位分类/images/颈部/0018_上斜负重头后仰_24081201.gif | M19: 24081201_withnewxunji.mp4 | P19: Incline Weighted Neck Extension / Weighted Neck Hyperextension on Incline Bench | Q19: 上斜负重颈后仰、斜板负重头后仰、上斜颈后伸 | R19: 站姿负重头后仰、俯卧颈后伸、器械颈部伸展
A20: 19 | B20: 24091201 | C20: 上斜负重颈弯举 | D20: 颈部 | G20: 其他 | H20: 哑铃、杠铃、上斜训练凳、负重片 | I20: weight | J20: gif | K20: 0019_上斜负重颈弯举_24091201.gif | L20: 训记_动作图片_GIF_按身体部位分类/images/颈部/0019_上斜负重颈弯举_24091201.gif | M20: 24091201_withnewxunji.mp4 | P20: Incline Weighted Neck Curl / Weighted Incline Neck Curl | Q20: 上斜颈弯举、负重上斜颈弯举、颈后弯举（上斜） | R20: 站姿颈弯举、俯卧颈弯举、器械颈屈伸
A21: 20 | B21: 24101201 | C21: 站姿负重头后仰 | D21: 颈部 | G21: 其他 | H21: 哑铃、杠铃片、颈后负重带 | I21: weight | J21: gif | K21: 0020_站姿负重头后仰_24101201.gif | L21: 训记_动作图片_GIF_按身体部位分类/images/颈部/0020_站姿负重头后仰_24101201.gif | M21: 24101201_withnewxunji.mp4 | P21: Weighted Standing Neck Extension / Standing Weighted Neck Extension | Q21: 负重头后仰、站姿头后仰、颈部负重后仰 | R21: 坐姿负重头后仰、徒手头后仰、俯身头后仰
A22: 21 | B22: 24111201 | C22: 绳索头后仰 | D22: 颈部 | G22: 其他 | H22: 绳索、高位滑轮、颈带（可选） | I22: weight | J22: gif | K22: 0021_绳索头后仰_24111201.gif | L22: 训记_动作图片_GIF_按身体部位分类/images/颈部/0021_绳索头后仰_24111201.gif | M22: 24111201_withnewxunji.mp4 | P22: Cable Neck Extension / Rope Neck Extension | Q22: 头后仰、绳索颈部后仰、颈部后仰 | R22: 徒手头后仰、器械颈部后伸、俯身头后仰
A23: 22 | B23: 24121201 | C23: 绳索颈弯举 | D23: 颈部 | G23: 其他 | H23: 绳索（龙门架附件）、龙门架、高位滑轮 | I23: weight | J23: gif | K23: 0022_绳索颈弯举_24121201.gif | L23: 训记_动作图片_GIF_按身体部位分类/images/颈部/0022_绳索颈弯举_24121201.gif | M23: 24121201_withnewxunji.mp4 | P23: Cable Neck Curl / Rope Neck Curl | Q23: 颈弯举、绳索颈部弯举、颈部绳索弯举 | R23: 徒手颈弯举、杠铃颈后弯举、弹力带颈弯举
A24: 23 | B24: 25011201 | C24: 杠铃上凳 | D24: 臀部 | E24: 股四头肌、臀大肌 | F24: 腘绳肌、臀中肌 | G24: 杠铃 | H24: 杠铃、训练凳 | I24: weight | J24: gif | K24: 0023_杠铃上凳_25011201.gif | L24: 训记_动作图片_GIF_按身体部位分类/images/臀部/0023_杠铃上凳_25011201.gif | M24: 25011201-Barbell-Step-up-(female)_Hips__withnewxunji.mp4 | P24: Barbell Step-Up / Barbell Bench Step-Up | Q24: 杠铃登凳、杠铃上台阶、杠铃踏凳 | R24: 哑铃上凳、保加利亚分腿蹲、杠铃弓步蹲
A25: 24 | B25: 26561201 | C25: 背后二头单边弯举 | D25: 二头 | E25: 肱二头肌外侧头、前臂 | F25: 肱二头肌 | G25: 绳索 | H25: 绳索器械、龙门架、绳索把手、缆绳训练器 | I25: weight | J25: gif | K25: 0024_背后二头单边弯举_26561201.gif | L25: 训记_动作图片_GIF_按身体部位分类/images/二头/0024_背后二头单边弯举_26561201.gif | M25: 26561201-Cable-One-Arm-Biceps-Curl-(VERSION-2)_Upper-Arms__withnewxunji.mp4 | P25: Behind-the-back single-arm cable curl / Single-arm rear bicep curl / Cable behind back bicep curl | Q25: 单边背后二头弯举、龙门架背后单臂弯举、单手背后绳索弯举、背后单侧二头弯举 | R25: 站姿单臂绳索弯举、集中弯举、锤式弯举
A26: 25 | B26: 26591208 | C26: 上斜悍马机推胸 | D26: 胸 | E26: 上胸、三角肌前束 | F26: 肱三头肌、胸大肌 | G26: 悍马机 | H26: 悍马器械、悍马机（Hammer Strength Machine）、上斜推胸器械 | I26: weight | J26: gif | K26: 0025_上斜悍马机推胸_26591208.gif | L26: 训记_动作图片_GIF_按身体部位分类/images/胸/0025_上斜悍马机推胸_26591208.gif | M26: 26591208-Lever-Incline-Chest-Press_withnewxunji.mp4 | P26: Incline Hammer Chest Press / Incline Machine Chest Press | Q26: 上斜哈克推胸、上斜器械推胸、上斜推胸、悍马机上斜推胸 | R26: 平板悍马机推胸、上斜哑铃卧推、器械夹胸
A27: 26 | B27: 27591201 | C27: 器械侧踢 | D27: 臀部 | E27: 臀中肌、臀大肌 | G27: 器械 | H27: 固定器械、侧踢训练器、髋外展器械 | I27: weight | J27: gif | K27: 0026_器械侧踢_27591201.gif | L27: 训记_动作图片_GIF_按身体部位分类/images/臀部/0026_器械侧踢_27591201.gif | M27: 27591201-Lever-Side-Hip-Abduction-(female)_Hips__withnewxunji.mp4 | P27: Machine Side Kick / Cable Hip Abduction (Machine) | Q27: 侧踢器械训练、器械臀部侧踢、健身房侧踢 | R27: 站姿绳索侧踢、仰卧侧抬腿、器械髋外展
A28: 27 | B28: 27841201 | C28: 扩胸开合 | D28: 热身动作 | E28: 上胸、胸大肌 | F28: 三头、三角前束、胸、三角肌前束 | G28: 自重 | H28: 自重、无需器械、自重训练 | I28: plus_weight | J28: gif | K28: 0027_扩胸开合_27841201.gif | L28: 训记_动作图片_GIF_按身体部位分类/images/热身动作/0027_扩胸开合_27841201.gif | M28: 27841201-Shoulder---Transverse-Flexion_withnewxunji.mp4 | P28: Chest Opener Clap / Arm Circles for Chest / Straight-Arm Chest Opener | Q28: 开合扩胸、扩胸运动、手臂开合扩胸、直臂扩胸 | R28: 肩部绕环、俯身扩胸拉伸、站姿胸部拉伸
A29: 28 | B29: 29501201 | C29: 犀牛腰带机深蹲 | D29: 腿 | E29: 股四头肌、腘绳肌 | F29: 臀大肌 | G29: 器械 | H29: 固定器械、犀牛腰带机、腰带深蹲机、Belt Squat Machine | I29: weight | J29: gif | K29: 0028_犀牛腰带机深蹲_29501201.gif | L29: 训记_动作图片_GIF_按身体部位分类/images/腿/0028_犀牛腰带机深蹲_29501201.gif | M29: 29501201-Lever-Belt-Squat_Thighs__withnewxunji.mp4 | P29: Belt Squat / Hip Belt Squat Machine | Q29: 腰带机深蹲、犀牛深蹲、髋 belt squat、belt squat | R29: 杠铃深蹲、腿举、哈克深蹲
A30: 29 | B30: 29681201 | C30: 哑铃火箭推 | D30: 腿 | E30: 三角肌前束、股四头肌 | F30: 臀大肌、三角肌中束、上胸、腘绳肌 | G30: 哑铃 | H30: 哑铃 | I30: weight | J30: gif | K30: 0029_哑铃火箭推_29681201.gif | L30: 训记_动作图片_GIF_按身体部位分类/images/腿/0029_哑铃火箭推_29681201.gif | M30: 29681201-Dumbbell-Thruster_Thighs_withnewxunji.mp4 | P30: Dumbbell Thruster / Dumbbell Rocket Push / Thruster with Dumbbells | Q30: 火箭推、哑铃火箭推举、哑铃前蹲推举、Dumbbell Thruster | R30: 杠铃火箭推、哑铃前蹲、哑铃肩推
A31: 30 | B31: 29791201 | C31: 平板交替手肘支撑 | D31: 核心稳定 | G31: 其他 | I31: weight | J31: gif | K31: 0030_平板交替手肘支撑_29791201.gif | L31: 训记_动作图片_GIF_按身体部位分类/images/核心稳定/0030_平板交替手肘支撑_29791201.gif | M31: 29791201-Elbow_withnewxunji.mp4 | P31: Alternating Elbow Plank / Plank with Alternating Elbow Support | Q31: 交替手肘平板支撑、手肘交替平板支撑、平板支撑交替手肘 | R31: 标准平板支撑、侧平板支撑、动态平板支撑
A32: 31 | B32: 33051201 | C32: 杠铃火箭推 | D32: 腿 | E32: 三角肌前束、股四头肌 | F32: 臀大肌、三角肌中束、上胸、腘绳肌 | G32: 杠铃 | H32: 杠铃 | I32: weight | J32: gif | K32: 0031_杠铃火箭推_33051201.gif | L32: 训记_动作图片_GIF_按身体部位分类/images/腿/0031_杠铃火箭推_33051201.gif | M32: 33051201-Barbell-Thruster_Weightlifting__withnewxunji.mp4 | P32: Barbell Thruster / Thruster | Q32: 火箭推、杠铃推举深蹲、深蹲推举 | R32: 哑铃火箭推、壶铃火箭推、前蹲推举
A33: 32 | B33: 33431201 | C33: 器械把手侧平举 | D33: 肩 | E33: 三角肌中束、三角肌前束 | F33: 三角肌后束 | G33: 器械 | H33: 固定器械、器械把手、固定式肩部训练机、龙门架（若适用） | I33: weight | J33: gif | K33: 0032_器械把手侧平举_33431201.gif | L33: 训记_动作图片_GIF_按身体部位分类/images/肩/0032_器械把手侧平举_33431201.gif | M33: 33431201-Lever-Lateral-Raise-bargrip_withnewxunji.mp4 | P33: Machine Lateral Raise / Cable Lateral Raise (with handle) / Machine Shoulder Abduction | Q33: 侧平举（器械）、器械侧平举、把手侧平举、坐姿器械侧平举 | R33: 哑铃侧平举、绳索侧平举、坐姿哑铃推举
A34: 33 | B34: 33441201 | C34: 器械坐姿下夹胸 | D34: 胸 | E34: 胸大肌、三角肌前束 | F34: 上胸 | G34: 器械 | H34: 固定器械、夹胸训练器、胸部训练器械、健身房固定器械 | I34: weight | J34: gif | K34: 0033_器械坐姿下夹胸_33441201.gif | L34: 训记_动作图片_GIF_按身体部位分类/images/胸/0033_器械坐姿下夹胸_33441201.gif | M34: 33441201-Lever-Crossovers_withnewxunji.mp4 | P34: Seated Machine Lower Chest Fly / Machine Decline Chest Fly / Lower Pec Fly | Q34: 坐姿下夹胸、器械下夹胸、下夹胸训练、坐姿器械夹胸 | R34: 器械坐姿夹胸、绳索下拉夹胸、仰卧下斜哑铃飞鸟
A35: 34 | B35: 35491201 | C35: 悍马机臀冲 | D35: 臀部 | E35: 臀中肌、臀大肌 | F35: 腘绳肌 | G35: 悍马机 | H35: 悍马器械、悍马机（Hammer Machine）、臀冲训练器 | I35: weight | J35: gif | K35: 0034_悍马机臀冲_35491201.gif | L35: 训记_动作图片_GIF_按身体部位分类/images/臀部/0034_悍马机臀冲_35491201.gif | M35: 35491201-Lever-Hip-Thrust-(plate-loaded)-(female)_Hips__withnewxunji.mp4 | P35: Hammer Machine Hip Thrust / Machine Hip Thrust | Q35: 锤式臀冲、悍马臀冲、器械臀冲、坐姿臀冲 | R35: 杠铃臀冲、自重臀桥、史密斯机臀冲
A36: 35 | B36: 36541201 | C36: 海豹杠铃划船 | D36: 背 | E36: 背阔肌、三角肌后束 | F36: 前臂 | G36: 杠铃 | H36: 杠铃、平板凳 | I36: weight | J36: gif | K36: 0035_海豹杠铃划船_36541201.gif | L36: 训记_动作图片_GIF_按身体部位分类/images/背/0035_海豹杠铃划船_36541201.gif | M36: 36541201-Barbell-Lying-Row-on-Rack_Back__withnewxunji.mp4 | P36: Seal Barbell Row / Barbell Seal Row | Q36: 杠铃海豹划船、海豹式杠铃划船、俯卧杠铃划船 | R36: 哑铃海豹划船、杠铃俯身划船、T杠划船
A37: 36 | B37: 40901201 | C37: 地雷杆硬拉 | D37: 臀部 | E37: 臀中肌、臀大肌 | F37: 腘绳肌 | G37: 杠铃 | H37: 地雷杆、杠铃、固定支架 | I37: weight | J37: gif | K37: 0036_地雷杆硬拉_40901201.gif | L37: 训记_动作图片_GIF_按身体部位分类/images/臀部/0036_地雷杆硬拉_40901201.gif | M37: 40901201-Landmine-Sumo-Squat-(male)_Hips__withnewxunji.mp4 | P37: Landmine Deadlift / Landmine Barbell Deadlift | Q37: 地雷管硬拉、地雷杠硬拉、Landmine硬拉、地雷式硬拉 | R37: 传统硬拉、罗马尼亚硬拉、相扑硬拉
A38: 37 | B38: 42471201 | C38: 地雷杆罗马尼亚硬拉 | D38: 臀部 | E38: 臀中肌、臀大肌 | F38: 腘绳肌 | G38: 杠铃 | H38: 地雷杆、杠铃、固定支架 | I38: weight | J38: gif | K38: 0037_地雷杆罗马尼亚硬拉_42471201.gif | L38: 训记_动作图片_GIF_按身体部位分类/images/臀部/0037_地雷杆罗马尼亚硬拉_42471201.gif | M38: 42471201-Landmine-Romanian-Deadlift-(VERSION-2)_Hips__withnewxunji.mp4 | P38: Landmine Romanian Deadlift / Landmine RDL | Q38: 地雷杆罗硬、罗马尼亚硬拉（地雷杆）、地雷管罗马尼亚硬拉 | R38: 传统罗马尼亚硬拉、哑铃罗马尼亚硬拉、相扑硬拉
A39: 38 | B39: 43361201 | C39: 坐姿器械二头弯举 | D39: 二头 | E39: 肱二头肌、前臂 | F39: 肱二头肌外侧头 | G39: 器械 | H39: 二头弯举器械、固定器械、健身房二头机 | I39: weight | J39: gif | K39: 0038_坐姿器械二头弯举_43361201.gif | L39: 训记_动作图片_GIF_按身体部位分类/images/二头/0038_坐姿器械二头弯举_43361201.gif | M39: 43361201-Lever-Biceps-Curl_Upper-Arms__withnewxunji.mp4 | P39: Seated Machine Bicep Curl / Machine Bicep Curl | Q39: 器械二头弯举、坐姿二头弯举、二头肌器械弯举、坐姿弯举 | R39: 哑铃坐姿二头弯举、站姿绳索二头弯举、杠铃二头弯举
A40: 39 | B40: 44211201 | C40: 俯身驴踢 | D40: 臀部 | E40: 臀中肌、腘绳肌 | F40: 臀大肌 | G40: 绳索 | H40: 绳索器械、踝部袖扣、龙门架 | I40: weight | J40: gif | K40: 0039_俯身驴踢_44211201.gif | L40: 训记_动作图片_GIF_按身体部位分类/images/臀部/0039_俯身驴踢_44211201.gif | M40: 44211201-Cable-Donkey-Kickback_Hips_withnewxunji.mp4 | P40: Cable Donkey Kick / Donkey Kick (Cable) | Q40: 驴踢、俯身绳索驴踢、绳索驴踢 | R40: 跪姿后踢腿、站姿绳索后踢、臀桥
...

Sheet 原始资源
A1: 序号 | B1: 动作Key/ID | C1: 动作名称 | D1: 身体部位分类 | E1: 主要肌群 | F1: 次要肌群 | G1: 全部目标肌群 | H1: 器械分类 | I1: 器械 | J1: 训练类型 | K1: 英文名 | L1: 别名 | M1: 相关动作 | N1: 本地媒体文件 | O1: 图片相对路径 | P1: 媒体类型 | Q1: APK资源原名 | R1: APK资源目录 | S1: APK物理路径 | T1: 媒体尺寸 | U1: 媒体Hash | V1: 原始mp4字段 | W1: 主视频URL | X1: 动作讲解视频相对路径 | Y1: 动作讲解视频URL | Z1: 讲解视频封面相对路径 | AA1: 讲解视频封面URL | AB1: detailDesc
A2: 1 | B2: 10431201 | C2: 负重颈弯举 | D2: 颈部 | H2: 其他 | I2: 杠铃、哑铃、颈部训练器、负重带 | J2: weight | K2: Weighted Neck Curl / Weighted Neck Flexion | L2: 颈弯举、负重颈部弯举、颈部负重弯举 | M2: 徒手颈弯举、颈部抗阻屈伸、仰卧颈弯举 | N2: 0001_负重颈弯举_10431201.gif | O2: images/颈部/0001_负重颈弯举_10431201.gif | P2: gif | Q2: 10431201 | R2: /assets/src/assets/neck | S2: res/FH.gif | T2: 288x162 | U2: d02f1d6f533c2005245084f2560c1fea | V2: 10431201_withnewxunji.mp4
A3: 2 | B3: 13001201 | C3: 下斜悍马机推胸 | D3: 胸 | E3: 胸大肌、三角肌前束 | F3: 上胸、肱三头肌 | G3: 胸大肌、三角肌前束、上胸、肱三头肌 | H3: 悍马机 | I3: 悍马器械、悍马机（Hammer Strength器械）、固定轨迹推胸器械 | J3: weight | K3: Decline Hammer Chest Press / Hammer Strength Decline Chest Press | L3: 悍马机下斜推胸、下斜推胸（器械）、器械下斜推胸、哈克机下斜推胸 | M3: 平板悍马机推胸、上斜悍马机推胸、器械坐姿推胸 | N3: 0002_下斜悍马机推胸_13001201.gif | O3: images/胸/0002_下斜悍马机推胸_13001201.gif | P3: gif | Q3: 13001201-Lever-Decline-Chest-Press_Chest_ | R3: /assets/src/assets/chest | S3: res/fr.gif | T3: 288x162 | U3: 9ac109dffb603ec5e06ab6e4d444c9c1 | V3: 13001201-Lever-Decline-Chest-Press_Chest__withnewxunji.mp4 | AB3: 下斜悍马机推胸_xiaoxie_2.mp4
A4: 3 | B4: 13461201 | C4: 跪姿前伸手 | D4: 热身动作 | E4: 背阔肌、背 | F4: 三角肌后束 | G4: 背阔肌、背、三角肌后束 | H4: 自重 | I4: 自重、瑜伽垫 | J4: plus_weight | K4: Kneeling Forward Reach / Kneeling Lat Stretch / Single-Arm Kneeling Reach | L4: 跪姿前伸展、跪姿手臂前伸、跪姿背阔肌拉伸、单臂跪姿前伸 | M4: 猫牛式、站姿背阔肌拉伸、婴儿式 | N4: 0003_跪姿前伸手_13461201.gif | O4: images/热身动作/0003_跪姿前伸手_13461201.gif | P4: gif | Q4: 13461201-Kneeling-Lat-Stretch_Back | R4: /assets/src/assets/back | S4: res/UN.gif | T4: 288x162 | U4: e6c11d1f47cc56ae597d7c4c95124efa | V4: 13461201-Kneeling-Lat-Stretch_Back_withnewxunji.mp4 | AB4: 跪姿前伸手_xiaoxie_2.mp4
A5: 4 | B5: 13471201 | C5: 单手悍马机下拉 | D5: 背 | E5: 背阔肌、三角肌后束 | F5: 前臂、斜方肌 | G5: 背阔肌、三角肌后束、前臂、斜方肌 | H5: 悍马机 | I5: 悍马器械、悍马机（Hammer Strength器械） | J5: weight | K5: Single-Arm Hammer Strength Lat Pulldown / One-Arm Hammer Lat Pulldown | L5: 悍马机单手下拉、单臂悍马下拉、单手哈玛机下拉 | M5: 坐姿绳索高位下拉、单臂哑铃划船、直臂下压 | N5: 0004_单手悍马机下拉_13471201.gif | O5: images/背/0004_单手悍马机下拉_13471201.gif | P5: gif | Q5: 13471201-Lever-One-Arm-Lateral-Wide-Pulldown-(plate-loaded)_Back | R5: /assets/src/assets/back | S5: res/Ap.gif | T5: 288x162 | U5: 925f066ae9089ac0ebed4657d58ac0a2 | V5: 13471201-Lever-One-Arm-Lateral-Wide-Pulldown-(plate-loaded)_Back_withnewxunji.mp4 | AB5: 单手悍马机下拉_xiaoxie_2.mp4
A6: 5 | B6: 13501201 | C6: 器械划船1 | D6: 背 | E6: 背阔肌、三角肌后束 | F6: 前臂 | G6: 背阔肌、三角肌后束、前臂 | H6: 器械 | I6: 固定器械、划船器械、坐姿划船机 | J6: weight | K6: Machine Row / Seated Machine Row | L6: 器械划船、坐姿器械划船、背部器械划船 | M6: 哑铃划船、杠铃划船、高位下拉 | N6: 0005_器械划船1_13501201.gif | O6: images/背/0005_器械划船1_13501201.gif | P6: gif | Q6: 13501201-Lever-Seated-Row_Back | R6: /assets/src/assets/back | S6: res/WP.gif | T6: 288x162 | U6: e2b80c22c92c405113c25431b44603a6 | V6: 13501201-Lever-Seated-Row_Back_withnewxunji.mp4
A7: 6 | B7: 15331201 | C7: 抓举 | D7: 腿 | E7: 股四头肌、腘绳肌 | F7: 臀大肌 | G7: 股四头肌、腘绳肌、臀大肌 | H7: 杠铃 | I7: 杠铃 | J7: weight | K7: Snatch / Barbell Snatch | L7: 杠铃抓举、抓举动作、抓举训练 | M7: 高翻、硬拉、深蹲 | N7: 0006_抓举_15331201.gif | O7: images/腿/0006_抓举_15331201.gif | P7: gif | Q7: 15331201-Barbell-Snatch_Weightlifts_ | R7: /assets/src/assets/leg | S7: res/d1.gif | T7: 288x162 | U7: 8b4c2600e6fae15c05a437a99d273135 | V7: 15331201-Barbell-Snatch_Weightlifts__withnewxunji.mp4
A8: 7 | B8: 15971201 | C8: 史密斯罗马尼亚硬拉 | D8: 臀部 | E8: 臀中肌、腘绳肌 | F8: 臀大肌 | G8: 臀中肌、腘绳肌、臀大肌 | H8: 史密斯机 | I8: 史密斯机、杠铃（固定于史密斯机） | J8: weight | K8: Smith Machine Romanian Deadlift / Smith RDL | L8: 史密斯机罗马尼亚硬拉、罗马尼亚硬拉（史密斯机）、史密斯直腿硬拉 | M8: 传统罗马尼亚硬拉、哑铃罗马尼亚硬拉、史密斯臀桥 | N8: 0007_史密斯罗马尼亚硬拉_15971201.gif | O8: images/臀部/0007_史密斯罗马尼亚硬拉_15971201.gif | P8: gif | Q8: 15971201-Smith-Stiff-Legged-Deadlift_Hips_ | R8: /assets/src/assets/hips | S8: res/Af.gif | T8: 288x162 | U8: 34de25a568353f2a8526c3159634b737 | V8: 15971201-Smith-Stiff-Legged-Deadlift_Hips__withnewxunji.mp4 | AB8: 史密斯罗马尼亚硬拉_gandy_2.mp4
A9: 8 | B9: 18571201 | C9: 坐姿器械卷腹 | D9: 腹部 | E9: 腹直肌、腹斜肌 | G9: 腹直肌、腹斜肌 | H9: 器械 | I9: 固定器械、卷腹器械、腹部训练机 | J9: weight | K9: Seated Machine Crunch / Machine Crunch | L9: 器械卷腹、坐姿卷腹、卷腹器械训练 | M9: 仰卧卷腹、绳索卷腹、悬垂举腿 | N9: 0008_坐姿器械卷腹_18571201.gif | O9: images/腹部/0008_坐姿器械卷腹_18571201.gif | P9: gif | Q9: 18571201-Lever-Total-Abdominal-Crunch_Waist | R9: /assets/src/assets/cores | S9: res/LT.gif | T9: 288x162 | U9: 6e12a9e308e4f311948a06c17a168e71 | V9: 18571201-Lever-Total-Abdominal-Crunch_Waist_withnewxunji.mp4
A10: 9 | B10: 18651201 | C10: 对握引体向上 | D10: 背 | E10: 背阔肌、背 | F10: 三角肌后束、前臂、斜方肌、肱二头肌、肱二头肌外侧头 | G10: 背阔肌、背、三角肌后束、前臂、斜方肌、肱二头肌、肱二头肌外侧头 | H10: 自重 | I10: 自重、单杠、引体向上杆、健身房单杠 | J10: plus_weight | K10: Neutral-Grip Pull-Up / Hammer Grip Pull-Up / Parallel Grip Pull-Up | L10: 反握引体向上、中性握引体向上、掌心相对引体向上 | M10: 正握引体向上、反握引体向上、宽握引体向上 | N10: 0009_对握引体向上_18651201.gif | O10: images/背/0009_对握引体向上_18651201.gif | P10: gif | Q10: 18651201-Hammer-Grip-Pull-up-on-Dip-Cage_Back | R10: /assets/src/assets/back | S10: res/cE.gif | T10: 288x162 | U10: 557605cbc494560655d10555f7bc2ecb | V10: 18651201-Hammer-Grip-Pull-up-on-Dip-Cage_Back_withnewxunji.mp4 | AB10: https://tupian.xunjiapp.cn/xunji_bunny/1763694625142_bunny.mp4
A11: 10 | B11: 18761201 | C11: 悍马机侧平举 | D11: 肩 | E11: 三角肌中束、三角肌前束 | F11: 三角肌后束 | G11: 三角肌中束、三角肌前束、三角肌后束 | H11: 悍马机 | I11: 悍马器械、悍马机、固定器械 | J11: weight | K11: Hammer Machine Lateral Raise / Machine Lateral Raise | L11: 侧平举（悍马机）、悍马侧平举、器械侧平举 | M11: 哑铃侧平举、绳索侧平举、坐姿器械推举 | N11: 0010_悍马机侧平举_18761201.gif | O11: images/肩/0010_悍马机侧平举_18761201.gif | P11: gif | Q11: 18761201-Lever-Lateral-Raise-hammer | R11: /assets/src/assets/shoulder | S11: res/59.gif | T11: 288x162 | U11: be79515f4581e7d3489e8c30c11af624 | V11: 18761201-Lever-Lateral-Raise-hammer_withnewxunji.mp4 | AB11: 悍马机侧平举_xiaoxie_2.mp4
A12: 11 | B12: 21421201 | C12: 滑雪机 | D12: 有氧 | H12: 其他 | I12: 滑雪机 | J12: times | K12: SkiErg / Ski Ergometer / Ski Machine | L12: 滑雪机训练、滑雪机有氧、滑雪机运动、室内滑雪机 | M12: 划船机、椭圆机、登山机 | N12: 0011_滑雪机_21421201.gif | O12: images/有氧/0011_滑雪机_21421201.gif | P12: gif | Q12: 21421201-Ski-Ergometer_Cardio_ | R12: /assets/src/assets/cardio | S12: res/eB.gif | T12: 288x162 | U12: 33f17434ec11c13660178f8f6ac99812 | V12: 21421201-Ski-Ergometer_Cardio__withnewxunji.mp4
A13: 12 | B13: 21461201 | C13: 器械臀冲 | D13: 臀部 | E13: 臀中肌、臀大肌 | F13: 腘绳肌 | G13: 臀中肌、臀大肌、腘绳肌 | H13: 器械 | I13: 固定器械、臀冲训练机、髋部推举器械、带臀垫和脚垫的固定器械 | J13: weight | K13: Machine Hip Thrust / Hip Thrust Machine | L13: 臀冲（器械版）、机器臀冲、坐姿器械臀冲、器械髋部推举 | M13: 杠铃臀冲、自重臀桥、史密斯机臀冲 | N13: 0012_器械臀冲_21461201.gif | O13: images/臀部/0012_器械臀冲_21461201.gif | P13: gif | Q13: 21461201-Lever-Hip-Thrust_Hips | R13: /assets/src/assets/hips | S13: res/xB.gif | T13: 288x162 | U13: 19182fbdc6db0766b3c087ee48638f04 | V13: 21461201-Lever-Hip-Thrust_Hips_withnewxunji.mp4 | AB13: 器械臀冲_xiaoxie_2.mp4
A14: 13 | B14: 21501201 | C14: 弹力带侧躺腿外展 | D14: 臀部 | E14: 臀中肌、臀大肌 | G14: 臀中肌、臀大肌 | H14: TRX&弹力带 | I14: 弹力带、阻力带 | J14: weight | K14: Banded Side-Lying Leg Abduction / Resistance Band Side Leg Lift | L14: 侧躺弹力带腿外展、弹力带侧卧腿外展、侧卧弹力带臀中肌训练 | M14: 侧卧腿上抬、弹力带站姿腿外展、侧卧蚌式开合 | N14: 0013_弹力带侧躺腿外展_21501201.gif | O14: images/臀部/0013_弹力带侧躺腿外展_21501201.gif | P14: gif | Q14: 21501201-Resistance-Band-Clam_Hips_ | R14: /assets/src/assets/hips | S14: res/4A.gif | T14: 288x162 | U14: 424f07c662ce95ccb66eea2b2ae5a920 | V14: 21501201-Resistance-Band-Clam_Hips__withnewxunji.mp4
A15: 14 | B15: 22211201 | C15: 哑铃上凳 | D15: 臀部 | E15: 股四头肌、臀大肌 | F15: 腘绳肌、臀中肌 | G15: 股四头肌、臀大肌、腘绳肌、臀中肌 | H15: 哑铃 | I15: 哑铃、训练凳（或台阶） | J15: weight | K15: Dumbbell Step-Up / DB Step Up | L15: 上凳哑铃、哑铃踏凳、哑铃登阶 | M15: 杠铃上凳、徒手上凳、哑铃弓步 | N15: 0014_哑铃上凳_22211201.gif | O15: images/臀部/0014_哑铃上凳_22211201.gif | P15: gif | Q15: 22211201-Dumbbell-Step-Up-(female)_Thighs_ | R15: /assets/src/assets/hips | S15: res/Mg.gif | T15: 288x162 | U15: 0937552f21e26c5f0f85325348d3e04d | V15: 22211201-Dumbbell-Step-Up-(female)_Thighs__withnewxunji.mp4 | AB15: 哑铃上凳2_tingting_2.mp4
A16: 15 | B16: 22651201 | C16: 器械划船2 | D16: 背 | E16: 背阔肌、三角肌后束 | F16: 前臂 | G16: 背阔肌、三角肌后束、前臂 | H16: 器械 | I16: 固定器械、划船机、坐姿划船器械 | J16: weight | K16: Machine Row / Seated Machine Row | L16: 器械划船、坐姿器械划船、机器划船 | M16: 杠铃划船、哑铃划船、高位下拉 | N16: 0015_器械划船2_22651201.gif | O16: images/背/0015_器械划船2_22651201.gif | P16: gif | Q16: 22651201-Lever-Seated-Row-(version-2)_Back | R16: /assets/src/assets/back | S16: res/-S.gif | T16: 288x162 | U16: 38f230df59e92d09411028cf47cb62eb | V16: 22651201-Lever-Seated-Row-(version-2)_Back_withnewxunji.mp4 | AB16: 器械划船_版本2_xiaoxie_2.mp4
A17: 16 | B17: 22861201 | C17: 器械驴踢 | D17: 臀部 | E17: 臀中肌、腘绳肌 | F17: 臀大肌 | G17: 臀中肌、腘绳肌、臀大肌 | H17: 器械 | I17: 固定器械、器械驴踢机、臀部训练机、固定式驴踢训练器 | J17: weight | K17: Machine Donkey Kick / Cable Donkey Kick (machine version) | L17: 驴踢（器械）、器械臀踢、机器驴踢、坐姿器械驴踢 | M17: 徒手驴踢、弹力带驴踢、跪姿后踢腿 | N17: 0016_器械驴踢_22861201.gif | O17: images/臀部/0016_器械驴踢_22861201.gif | P17: gif | Q17: 22861201-Lever-Hip-Extension-(VERSION-2)_Hips_ | R17: /assets/src/assets/hips | S17: res/ct.gif | T17: 288x162 | U17: 21d94268dc553a2a99df0aae1746c199 | V17: 22861201-Lever-Hip-Extension-(VERSION-2)_Hips__withnewxunji.mp4
A18: 17 | B18: 23131201 | C18: 绳索内收 | D18: 臀部 | E18: 臀中肌、臀大肌 | G18: 臀中肌、臀大肌 | H18: 绳索 | I18: 绳索器械、龙门架、缆绳机 | J18: weight | K18: Cable Hip Adduction / Cable Inner Thigh | L18: 绳索臀内收、缆绳内收、绳索侧抬腿、绳索髋内收 | M18: 站姿绳索外展、侧卧髋内收、器械髋内收 | N18: 0017_绳索内收_23131201.gif | O18: images/臀部/0017_绳索内收_23131201.gif | P18: gif | Q18: 23131201-Cable-Hip-Adduction-(female)_Hips | R18: /assets/src/assets/hips | S18: res/5q.gif | T18: 288x162 | U18: b92947739b6bbafe851b027236988c07 | V18: 23131201-Cable-Hip-Adduction-(female)_Hips_withnewxunji.mp4 | AB18: 绳索内收_gandy_2.mp4
A19: 18 | B19: 24081201 | C19: 上斜负重头后仰 | D19: 颈部 | H19: 其他 | I19: 上斜训练凳、杠铃片、颈后负重带 | J19: weight | K19: Incline Weighted Neck Extension / Weighted Neck Hyperextension on Incline Bench | L19: 上斜负重颈后仰、斜板负重头后仰、上斜颈后伸 | M19: 站姿负重头后仰、俯卧颈后伸、器械颈部伸展 | N19: 0018_上斜负重头后仰_24081201.gif | O19: images/颈部/0018_上斜负重头后仰_24081201.gif | P19: gif | Q19: 24081201 | R19: /assets/src/assets/neck | S19: res/y6.gif | T19: 288x162 | U19: 8e3f62f0a2066fd4aa8dc102b5c43f2e | V19: 24081201_withnewxunji.mp4
A20: 19 | B20: 24091201 | C20: 上斜负重颈弯举 | D20: 颈部 | H20: 其他 | I20: 哑铃、杠铃、上斜训练凳、负重片 | J20: weight | K20: Incline Weighted Neck Curl / Weighted Incline Neck Curl | L20: 上斜颈弯举、负重上斜颈弯举、颈后弯举（上斜） | M20: 站姿颈弯举、俯卧颈弯举、器械颈屈伸 | N20: 0019_上斜负重颈弯举_24091201.gif | O20: images/颈部/0019_上斜负重颈弯举_24091201.gif | P20: gif | Q20: 24091201 | R20: /assets/src/assets/neck | S20: res/Jg.gif | T20: 288x162 | U20: 614e9304c18b96ba20f78c1c270a4383 | V20: 24091201_withnewxunji.mp4
A21: 20 | B21: 24101201 | C21: 站姿负重头后仰 | D21: 颈部 | H21: 其他 | I21: 哑铃、杠铃片、颈后负重带 | J21: weight | K21: Weighted Standing Neck Extension / Standing Weighted Neck Extension | L21: 负重头后仰、站姿头后仰、颈部负重后仰 | M21: 坐姿负重头后仰、徒手头后仰、俯身头后仰 | N21: 0020_站姿负重头后仰_24101201.gif | O21: images/颈部/0020_站姿负重头后仰_24101201.gif | P21: gif | Q21: 24101201 | R21: /assets/src/assets/neck | S21: res/e1.gif | T21: 288x162 | U21: 0ba617de1bf7e986638bc44be55f892f | V21: 24101201_withnewxunji.mp4
A22: 21 | B22: 24111201 | C22: 绳索头后仰 | D22: 颈部 | H22: 其他 | I22: 绳索、高位滑轮、颈带（可选） | J22: weight | K22: Cable Neck Extension / Rope Neck Extension | L22: 头后仰、绳索颈部后仰、颈部后仰 | M22: 徒手头后仰、器械颈部后伸、俯身头后仰 | N22: 0021_绳索头后仰_24111201.gif | O22: images/颈部/0021_绳索头后仰_24111201.gif | P22: gif | Q22: 24111201 | R22: /assets/src/assets/neck | S22: res/GE.gif | T22: 288x162 | U22: 443cb879818025b35a115be082941519 | V22: 24111201_withnewxunji.mp4
A23: 22 | B23: 24121201 | C23: 绳索颈弯举 | D23: 颈部 | H23: 其他 | I23: 绳索（龙门架附件）、龙门架、高位滑轮 | J23: weight | K23: Cable Neck Curl / Rope Neck Curl | L23: 颈弯举、绳索颈部弯举、颈部绳索弯举 | M23: 徒手颈弯举、杠铃颈后弯举、弹力带颈弯举 | N23: 0022_绳索颈弯举_24121201.gif | O23: images/颈部/0022_绳索颈弯举_24121201.gif | P23: gif | Q23: 24121201 | R23: /assets/src/assets/neck | S23: res/hT.gif | T23: 288x162 | U23: 021a22789a307007150e76472349cdea | V23: 24121201_withnewxunji.mp4
A24: 23 | B24: 25011201 | C24: 杠铃上凳 | D24: 臀部 | E24: 股四头肌、臀大肌 | F24: 腘绳肌、臀中肌 | G24: 股四头肌、臀大肌、腘绳肌、臀中肌 | H24: 杠铃 | I24: 杠铃、训练凳 | J24: weight | K24: Barbell Step-Up / Barbell Bench Step-Up | L24: 杠铃登凳、杠铃上台阶、杠铃踏凳 | M24: 哑铃上凳、保加利亚分腿蹲、杠铃弓步蹲 | N24: 0023_杠铃上凳_25011201.gif | O24: images/臀部/0023_杠铃上凳_25011201.gif | P24: gif | Q24: 25011201-Barbell-Step-up-(female)_Hips_ | R24: /assets/src/assets/hips | S24: res/Ov.gif | T24: 288x162 | U24: 61e89f7c67c7f00f70de37a2cbe430ad | V24: 25011201-Barbell-Step-up-(female)_Hips__withnewxunji.mp4 | AB24: 杠铃上凳_xiaoxie_2.mp4
A25: 24 | B25: 26561201 | C25: 背后二头单边弯举 | D25: 二头 | E25: 肱二头肌外侧头、前臂 | F25: 肱二头肌 | G25: 肱二头肌外侧头、前臂、肱二头肌 | H25: 绳索 | I25: 绳索器械、龙门架、绳索把手、缆绳训练器 | J25: weight | K25: Behind-the-back single-arm cable curl / Single-arm rear bicep curl / Cable behind back bicep curl | L25: 单边背后二头弯举、龙门架背后单臂弯举、单手背后绳索弯举、背后单侧二头弯举 | M25: 站姿单臂绳索弯举、集中弯举、锤式弯举 | N25: 0024_背后二头单边弯举_26561201.gif | O25: images/二头/0024_背后二头单边弯举_26561201.gif | P25: gif | Q25: 26561201-Cable-One-Arm-Biceps-Curl-(VERSION-2)_Upper-Arms_ | R25: /assets/src/assets/bicep | S25: res/LP.gif | T25: 288x162 | U25: f9189e43a9269d88f1474caaf6e77950 | V25: 26561201-Cable-One-Arm-Biceps-Curl-(VERSION-2)_Upper-Arms__withnewxunji.mp4 | AB25: 背后二头单边弯举_gandy_2.mp4
A26: 25 | B26: 26591208 | C26: 上斜悍马机推胸 | D26: 胸 | E26: 上胸、三角肌前束 | F26: 肱三头肌、胸大肌 | G26: 上胸、三角肌前束、肱三头肌、胸大肌 | H26: 悍马机 | I26: 悍马器械、悍马机（Hammer Strength Machine）、上斜推胸器械 | J26: weight | K26: Incline Hammer Chest Press / Incline Machine Chest Press | L26: 上斜哈克推胸、上斜器械推胸、上斜推胸、悍马机上斜推胸 | M26: 平板悍马机推胸、上斜哑铃卧推、器械夹胸 | N26: 0025_上斜悍马机推胸_26591208.gif | O26: images/胸/0025_上斜悍马机推胸_26591208.gif | P26: gif | Q26: 26591208-Lever-Incline-Chest-Press | R26: /assets/src/assets/chest | S26: res/eQ.gif | T26: 288x162 | U26: 869def1df37904aa72db943fa61b8af2 | V26: 26591208-Lever-Incline-Chest-Press_withnewxunji.mp4 | AB26: 上斜悍马机推胸_xiaoxie_2.mp4
A27: 26 | B27: 27591201 | C27: 器械侧踢 | D27: 臀部 | E27: 臀中肌、臀大肌 | G27: 臀中肌、臀大肌 | H27: 器械 | I27: 固定器械、侧踢训练器、髋外展器械 | J27: weight | K27: Machine Side Kick / Cable Hip Abduction (Machine) | L27: 侧踢器械训练、器械臀部侧踢、健身房侧踢 | M27: 站姿绳索侧踢、仰卧侧抬腿、器械髋外展 | N27: 0026_器械侧踢_27591201.gif | O27: images/臀部/0026_器械侧踢_27591201.gif | P27: gif | Q27: 27591201-Lever-Side-Hip-Abduction-(female)_Hips_ | R27: /assets/src/assets/hips | S27: res/B9.gif | T27: 288x162 | U27: e733c1ba968e50fa9dffa4900acbe567 | V27: 27591201-Lever-Side-Hip-Abduction-(female)_Hips__withnewxunji.mp4 | AB27: 器械侧踢_xiaoxie_2.mp4
A28: 27 | B28: 27841201 | C28: 扩胸开合 | D28: 热身动作 | E28: 上胸、胸大肌 | F28: 三头、三角前束、胸、三角肌前束 | G28: 上胸、胸大肌、三头、三角前束、胸、三角肌前束、背阔肌 | H28: 自重 | I28: 自重、无需器械、自重训练 | J28: plus_weight | K28: Chest Opener Clap / Arm Circles for Chest / Straight-Arm Chest Opener | L28: 开合扩胸、扩胸运动、手臂开合扩胸、直臂扩胸 | M28: 肩部绕环、俯身扩胸拉伸、站姿胸部拉伸 | N28: 0027_扩胸开合_27841201.gif | O28: images/热身动作/0027_扩胸开合_27841201.gif | P28: gif | Q28: 27841201-Shoulder---Transverse-Flexion | R28: /assets/src/assets/chest | S28: res/EF1.gif | T28: 270x270 | U28: 25bb87967c946119fb2de70e9829c29c | V28: 27841201-Shoulder---Transverse-Flexion_withnewxunji.mp4
A29: 28 | B29: 29501201 | C29: 犀牛腰带机深蹲 | D29: 腿 | E29: 股四头肌、腘绳肌 | F29: 臀大肌 | G29: 股四头肌、腘绳肌、臀大肌 | H29: 器械 | I29: 固定器械、犀牛腰带机、腰带深蹲机、Belt Squat Machine | J29: weight | K29: Belt Squat / Hip Belt Squat Machine | L29: 腰带机深蹲、犀牛深蹲、髋 belt squat、belt squat | M29: 杠铃深蹲、腿举、哈克深蹲 | N29: 0028_犀牛腰带机深蹲_29501201.gif | O29: images/腿/0028_犀牛腰带机深蹲_29501201.gif | P29: gif | Q29: 29501201-Lever-Belt-Squat_Thighs_ | R29: /assets/src/assets/leg | S29: res/u_.gif | T29: 288x162 | U29: 8c5d0366d8c90ac00235e0fddf6131ac | V29: 29501201-Lever-Belt-Squat_Thighs__withnewxunji.mp4 | AB29: 腰带机深蹲_xiaoxie_2.mp4
A30: 29 | B30: 29681201 | C30: 哑铃火箭推 | D30: 腿 | E30: 三角肌前束、股四头肌 | F30: 臀大肌、三角肌中束、上胸、腘绳肌 | G30: 三角肌前束、股四头肌、臀大肌、三角肌中束、上胸、腘绳肌 | H30: 哑铃 | I30: 哑铃 | J30: weight | K30: Dumbbell Thruster / Dumbbell Rocket Push / Thruster with Dumbbells | L30: 火箭推、哑铃火箭推举、哑铃前蹲推举、Dumbbell Thruster | M30: 杠铃火箭推、哑铃前蹲、哑铃肩推 | N30: 0029_哑铃火箭推_29681201.gif | O30: images/腿/0029_哑铃火箭推_29681201.gif | P30: gif | Q30: 29681201-Dumbbell-Thruster_Thighs | R30: /assets/src/assets/leg | S30: res/Iw.gif | T30: 288x162 | U30: f2d2749be49579f9f650bcf193baa5cf | V30: 29681201-Dumbbell-Thruster_Thighs_withnewxunji.mp4 | AB30: 哑铃火箭推2024_gandy_2.mp4
A31: 30 | B31: 29791201 | C31: 平板交替手肘支撑 | D31: 核心稳定 | H31: 其他 | J31: weight | K31: Alternating Elbow Plank / Plank with Alternating Elbow Support | L31: 交替手肘平板支撑、手肘交替平板支撑、平板支撑交替手肘 | M31: 标准平板支撑、侧平板支撑、动态平板支撑 | N31: 0030_平板交替手肘支撑_29791201.gif | O31: images/核心稳定/0030_平板交替手肘支撑_29791201.gif | P31: gif | Q31: 29791201-Elbow | R31: /assets/src/assets/corestable | S31: res/Aj1.gif | T31: 288x162 | U31: 8a20696fc6e2d8616658ef60983c08d8 | V31: 29791201-Elbow_withnewxunji.mp4 | AB31: 平板交替手肘支撑_gandy__tingting_2.mp4
A32: 31 | B32: 33051201 | C32: 杠铃火箭推 | D32: 腿 | E32: 三角肌前束、股四头肌 | F32: 臀大肌、三角肌中束、上胸、腘绳肌 | G32: 三角肌前束、股四头肌、臀大肌、三角肌中束、上胸、腘绳肌 | H32: 杠铃 | I32: 杠铃 | J32: weight | K32: Barbell Thruster / Thruster | L32: 火箭推、杠铃推举深蹲、深蹲推举 | M32: 哑铃火箭推、壶铃火箭推、前蹲推举 | N32: 0031_杠铃火箭推_33051201.gif | O32: images/腿/0031_杠铃火箭推_33051201.gif | P32: gif | Q32: 33051201-Barbell-Thruster_Weightlifting_ | R32: /assets/src/assets/leg | S32: res/lz.gif | T32: 288x162 | U32: 12a989c9d53ede6cb35651531bc8ad5c | V32: 33051201-Barbell-Thruster_Weightlifting__withnewxunji.mp4 | AB32: 杠铃火箭推_xiaoxie_2.mp4
A33: 32 | B33: 33431201 | C33: 器械把手侧平举 | D33: 肩 | E33: 三角肌中束、三角肌前束 | F33: 三角肌后束 | G33: 三角肌中束、三角肌前束、三角肌后束 | H33: 器械 | I33: 固定器械、器械把手、固定式肩部训练机、龙门架（若适用） | J33: weight | K33: Machine Lateral Raise / Cable Lateral Raise (with handle) / Machine Shoulder Abduction | L33: 侧平举（器械）、器械侧平举、把手侧平举、坐姿器械侧平举 | M33: 哑铃侧平举、绳索侧平举、坐姿哑铃推举 | N33: 0032_器械把手侧平举_33431201.gif | O33: images/肩/0032_器械把手侧平举_33431201.gif | P33: gif | Q33: 33431201-Lever-Lateral-Raise-bargrip | R33: /assets/src/assets/shoulder | S33: res/5i.gif | T33: 288x162 | U33: f7b92e84c26f12094c97598364d8acf2 | V33: 33431201-Lever-Lateral-Raise-bargrip_withnewxunji.mp4
A34: 33 | B34: 33441201 | C34: 器械坐姿下夹胸 | D34: 胸 | E34: 胸大肌、三角肌前束 | F34: 上胸 | G34: 胸大肌、三角肌前束、上胸 | H34: 器械 | I34: 固定器械、夹胸训练器、胸部训练器械、健身房固定器械 | J34: weight | K34: Seated Machine Lower Chest Fly / Machine Decline Chest Fly / Lower Pec Fly | L34: 坐姿下夹胸、器械下夹胸、下夹胸训练、坐姿器械夹胸 | M34: 器械坐姿夹胸、绳索下拉夹胸、仰卧下斜哑铃飞鸟 | N34: 0033_器械坐姿下夹胸_33441201.gif | O34: images/胸/0033_器械坐姿下夹胸_33441201.gif | P34: gif | Q34: 33441201-Lever-Crossovers | R34: /assets/src/assets/chest | S34: res/Be.gif | T34: 288x162 | U34: cd0708c4d39e53f94e5082fbe90d971d | V34: 33441201-Lever-Crossovers_withnewxunji.mp4
A35: 34 | B35: 35491201 | C35: 悍马机臀冲 | D35: 臀部 | E35: 臀中肌、臀大肌 | F35: 腘绳肌 | G35: 臀中肌、臀大肌、腘绳肌 | H35: 悍马机 | I35: 悍马器械、悍马机（Hammer Machine）、臀冲训练器 | J35: weight | K35: Hammer Machine Hip Thrust / Machine Hip Thrust | L35: 锤式臀冲、悍马臀冲、器械臀冲、坐姿臀冲 | M35: 杠铃臀冲、自重臀桥、史密斯机臀冲 | N35: 0034_悍马机臀冲_35491201.gif | O35: images/臀部/0034_悍马机臀冲_35491201.gif | P35: gif | Q35: 35491201-Lever-Hip-Thrust-(plate-loaded)-(female)_Hips_ | R35: /assets/src/assets/hips | S35: res/Rz1.gif | T35: 288x162 | U35: 55f369db4cef06ba7e4b78adce6b9d5f | V35: 35491201-Lever-Hip-Thrust-(plate-loaded)-(female)_Hips__withnewxunji.mp4
A36: 35 | B36: 36541201 | C36: 海豹杠铃划船 | D36: 背 | E36: 背阔肌、三角肌后束 | F36: 前臂 | G36: 背阔肌、三角肌后束、前臂 | H36: 杠铃 | I36: 杠铃、平板凳 | J36: weight | K36: Seal Barbell Row / Barbell Seal Row | L36: 杠铃海豹划船、海豹式杠铃划船、俯卧杠铃划船 | M36: 哑铃海豹划船、杠铃俯身划船、T杠划船 | N36: 0035_海豹杠铃划船_36541201.gif | O36: images/背/0035_海豹杠铃划船_36541201.gif | P36: gif | Q36: 36541201-Barbell-Lying-Row-on-Rack_Back_ | R36: /assets/src/assets/back | S36: res/3o2.gif | T36: 288x162 | U36: ec05e1c986696ffeae2a3bbfee452424 | V36: 36541201-Barbell-Lying-Row-on-Rack_Back__withnewxunji.mp4 | AB36: 海豹杠铃划船_xiaoxie_2.mp4
A37: 36 | B37: 40901201 | C37: 地雷杆硬拉 | D37: 臀部 | E37: 臀中肌、臀大肌 | F37: 腘绳肌 | G37: 臀中肌、臀大肌、腘绳肌 | H37: 杠铃 | I37: 地雷杆、杠铃、固定支架 | J37: weight | K37: Landmine Deadlift / Landmine Barbell Deadlift | L37: 地雷管硬拉、地雷杠硬拉、Landmine硬拉、地雷式硬拉 | M37: 传统硬拉、罗马尼亚硬拉、相扑硬拉 | N37: 0036_地雷杆硬拉_40901201.gif | O37: images/臀部/0036_地雷杆硬拉_40901201.gif | P37: gif | Q37: 40901201-Landmine-Sumo-Squat-(male)_Hips_ | R37: /assets/src/assets/hips | S37: res/bJ.gif | T37: 288x162 | U37: 5110eccaafcee43ccda649a67f99ede5 | V37: 40901201-Landmine-Sumo-Squat-(male)_Hips__withnewxunji.mp4 | AB37: 地雷杆硬拉_gandy_2.mp4
A38: 37 | B38: 42471201 | C38: 地雷杆罗马尼亚硬拉 | D38: 臀部 | E38: 臀中肌、臀大肌 | F38: 腘绳肌 | G38: 臀中肌、臀大肌、腘绳肌 | H38: 杠铃 | I38: 地雷杆、杠铃、固定支架 | J38: weight | K38: Landmine Romanian Deadlift / Landmine RDL | L38: 地雷杆罗硬、罗马尼亚硬拉（地雷杆）、地雷管罗马尼亚硬拉 | M38: 传统罗马尼亚硬拉、哑铃罗马尼亚硬拉、相扑硬拉 | N38: 0037_地雷杆罗马尼亚硬拉_42471201.gif | O38: images/臀部/0037_地雷杆罗马尼亚硬拉_42471201.gif | P38: gif | Q38: 42471201-Landmine-Romanian-Deadlift-(VERSION-2)_Hips_ | R38: /assets/src/assets/hips | S38: res/EB.gif | T38: 288x162 | U38: a4800f4ac58336f4beb729c8843d6b1e | V38: 42471201-Landmine-Romanian-Deadlift-(VERSION-2)_Hips__withnewxunji.mp4 | AB38: 地雷杆罗马尼亚硬拉_gandy_2.mp4
A39: 38 | B39: 43361201 | C39: 坐姿器械二头弯举 | D39: 二头 | E39: 肱二头肌、前臂 | F39: 肱二头肌外侧头 | G39: 肱二头肌、前臂、肱二头肌外侧头 | H39: 器械 | I39: 二头弯举器械、固定器械、健身房二头机 | J39: weight | K39: Seated Machine Bicep Curl / Machine Bicep Curl | L39: 器械二头弯举、坐姿二头弯举、二头肌器械弯举、坐姿弯举 | M39: 哑铃坐姿二头弯举、站姿绳索二头弯举、杠铃二头弯举 | N39: 0038_坐姿器械二头弯举_43361201.gif | O39: images/二头/0038_坐姿器械二头弯举_43361201.gif | P39: gif | Q39: 43361201-Lever-Biceps-Curl_Upper-Arms_ | R39: /assets/src/assets/bicep | S39: res/5S.gif | T39: 288x162 | U39: 557d94ba27b671c23154b8ea4978c7a8 | V39: 43361201-Lever-Biceps-Curl_Upper-Arms__withnewxunji.mp4 | AB39: 器械弯举_gandy__tingting_2.mp4
A40: 39 | B40: 44211201 | C40: 俯身驴踢 | D40: 臀部 | E40: 臀中肌、腘绳肌 | F40: 臀大肌 | G40: 臀中肌、腘绳肌、臀大肌 | H40: 绳索 | I40: 绳索器械、踝部袖扣、龙门架 | J40: weight | K40: Cable Donkey Kick / Donkey Kick (Cable) | L40: 驴踢、俯身绳索驴踢、绳索驴踢 | M40: 跪姿后踢腿、站姿绳索后踢、臀桥 | N40: 0039_俯身驴踢_44211201.gif | O40: images/臀部/0039_俯身驴踢_44211201.gif | P40: gif | Q40: 44211201-Cable-Donkey-Kickback_Hips | R40: /assets/src/assets/hips | S40: res/rk1.gif | T40: 288x162 | U40: ac9c8b89bb88a80dc9a34205221ced64 | V40: 44211201-Cable-Donkey-Kickback_Hips_withnewxunji.mp4 | AB40: 俯身驴踢_gandy_2.mp4
...

Sheet 分类统计
A1: 身体部位分类 | B1: 动作数量 | C1: 有本地媒体 | D1: 本地媒体覆盖率
A2: 颈部 | B2: =COUNTIF(动作库!$D$2:$D$1041,A2) | C2: =COUNTIFS(动作库!$D$2:$D$1041,A2,动作库!$K$2:$K$1041,"<>") | D2: =IFERROR(C2/B2,0)
A3: 胸 | B3: =COUNTIF(动作库!$D$2:$D$1041,A3) | C3: =COUNTIFS(动作库!$D$2:$D$1041,A3,动作库!$K$2:$K$1041,"<>") | D3: =IFERROR(C3/B3,0)
A4: 热身动作 | B4: =COUNTIF(动作库!$D$2:$D$1041,A4) | C4: =COUNTIFS(动作库!$D$2:$D$1041,A4,动作库!$K$2:$K$1041,"<>") | D4: =IFERROR(C4/B4,0)
A5: 背 | B5: =COUNTIF(动作库!$D$2:$D$1041,A5) | C5: =COUNTIFS(动作库!$D$2:$D$1041,A5,动作库!$K$2:$K$1041,"<>") | D5: =IFERROR(C5/B5,0)
A6: 腿 | B6: =COUNTIF(动作库!$D$2:$D$1041,A6) | C6: =COUNTIFS(动作库!$D$2:$D$1041,A6,动作库!$K$2:$K$1041,"<>") | D6: =IFERROR(C6/B6,0)
A7: 臀部 | B7: =COUNTIF(动作库!$D$2:$D$1041,A7) | C7: =COUNTIFS(动作库!$D$2:$D$1041,A7,动作库!$K$2:$K$1041,"<>") | D7: =IFERROR(C7/B7,0)
A8: 腹部 | B8: =COUNTIF(动作库!$D$2:$D$1041,A8) | C8: =COUNTIFS(动作库!$D$2:$D$1041,A8,动作库!$K$2:$K$1041,"<>") | D8: =IFERROR(C8/B8,0)
A9: 肩 | B9: =COUNTIF(动作库!$D$2:$D$1041,A9) | C9: =COUNTIFS(动作库!$D$2:$D$1041,A9,动作库!$K$2:$K$1041,"<>") | D9: =IFERROR(C9/B9,0)
A10: 有氧 | B10: =COUNTIF(动作库!$D$2:$D$1041,A10) | C10: =COUNTIFS(动作库!$D$2:$D$1041,A10,动作库!$K$2:$K$1041,"<>") | D10: =IFERROR(C10/B10,0)
A11: 二头 | B11: =COUNTIF(动作库!$D$2:$D$1041,A11) | C11: =COUNTIFS(动作库!$D$2:$D$1041,A11,动作库!$K$2:$K$1041,"<>") | D11: =IFERROR(C11/B11,0)
A12: 核心稳定 | B12: =COUNTIF(动作库!$D$2:$D$1041,A12) | C12: =COUNTIFS(动作库!$D$2:$D$1041,A12,动作库!$K$2:$K$1041,"<>") | D12: =IFERROR(C12/B12,0)
A13: 三头 | B13: =COUNTIF(动作库!$D$2:$D$1041,A13) | C13: =COUNTIFS(动作库!$D$2:$D$1041,A13,动作库!$K$2:$K$1041,"<>") | D13: =IFERROR(C13/B13,0)
... A21: Tabata | B21: =COUNTIF(动作库!$D$2:$D$1041,A21) | C21: =COUNTIFS(动作库!$D$2:$D$1041,A21,动作库!$K$2:$K$1041,"<>") | D21: =IFERROR(C21/B21,0)
A24: 数据概览 | B24: 数量
A25: 动作总数 | B25: 1040
A26: 可匹配APK本地媒体 | B26: 1035
A27: 其中GIF | B27: 1030
A28: 其中JPG | B28: 5
A29: 存在mp4字段 | B29: 885
A30: 存在明确完整主视频URL | B30: 404
A31: 存在动作讲解视频映射 | B31: 601

Sheet 字段说明
A1: 字段/文件 | B1: 说明
A2: 身体部位分类 | B2: 来自APK内动作元数据的 category 字段，共20类，不是根据动作名称人工猜测。
A3: 主要肌群/次要肌群 | B3: 来自APK内标准化 muscles.primary / muscles.secondary 数据。
A4: 本地媒体文件 | B4: 从APK资源中按动作URI依赖关系精确匹配后导出的文件名。
A5: 图片相对路径 | B5: 对应配套图片ZIP中的路径，例如 images/胸/xxxx.gif。
A6: APK资源原名 | B6: React Native registerAsset 中的原始资源名称。
A7: APK物理路径 | B7: APK内部资源混淆后的实际文件路径，例如 res/us1.gif。
A8: 原始mp4字段 | B8: 动作对象中的原始 mp4 字段；有些是完整URL，有些只是文件名。
A9: 主视频URL | B9: 只保留APK里已经明确写成完整URL的地址，没有擅自拼接。
A10: 动作讲解视频相对路径 | B10: APK内 videodescription 映射表中的讲解视频相对路径。
A11: 图片交付方式 | B11: Excel与图片ZIP分开提供；ZIP内按身体部位建立文件夹，GIF保持原格式。
A12: 未匹配本地媒体 | B12: 1040个动作中有5个未在该基础APK内找到可精确匹配的本地图片/GIF。
